Workbook

Sheet Dashboard
A1: Customer Transactions Dashboard
A2: ="Data as of "&TEXT(TODAY(),"dd mmm yyyy")&" | Dataset: "&COUNT('Final Project Dataset'!$B$2:$B$251)&" transactions" -> Data as of 30 Oct 2026 | Dataset: 250 transactions
A3: Region (slicer) | B3: South | C3: ◄ Slicer-style drop-downs and date range drive every KPI, table and chart (see HowTo for native Slicers/Timeline).
A4: Product (slicer) | B4: Smartwatch
A5: From date (timeline) | B5: 45658
A6: To date (timeline) | B6: 46022
G7: Top 5 Customers (all time)
A8: VOLUME KPIs | B8: Value | G8: # | H8: Customer | I8: Sales (₹) | J8: Profit (₹) | K8: Txns
A9: Total Sales | B9: =Pivot_Tables!B15 -> 89673 | G9: =High_Value_Customers!M8 -> 1 | H9: =High_Value_Customers!N8 -> Aditya Kapoor | I9: =High_Value_Customers!O8 -> 321673 | J9: =High_Value_Customers!P8 -> 53148.24 | K9: =High_Value_Customers!Q8 -> 6
A10: Total Profit | B10: =Pivot_Tables!C15 -> 15915.68 | G10: =High_Value_Customers!M9 -> 2 | H10: =High_Value_Customers!N9 -> Aditya Mehta | I10: =High_Value_Customers!O9 -> 249362 | J10: =High_Value_Customers!P9 -> 29285.42 | K10: =High_Value_Customers!Q9 -> 6
A11: Transactions | B11: =Pivot_Tables!D15 -> 3 | G11: =High_Value_Customers!M10 -> 3 | H11: =High_Value_Customers!N10 -> Riya Reddy | I11: =High_Value_Customers!O10 -> 237530 | J11: =High_Value_Customers!P10 -> 34908.45 | K11: =High_Value_Customers!Q10 -> 8
A12: Units Sold | B12: =Pivot_Tables!E15 -> 11 | G12: =High_Value_Customers!M11 -> 4 | H12: =High_Value_Customers!N11 -> Priya Iyer | I12: =High_Value_Customers!O11 -> 173827 | J12: =High_Value_Customers!P11 -> 28056.65 | K12: =High_Value_Customers!Q11 -> 4
G13: =High_Value_Customers!M12 -> 5 | H13: =High_Value_Customers!N12 -> Vihaan Mehta | I13: =High_Value_Customers!O12 -> 153202 | J13: =High_Value_Customers!P12 -> 22319.83 | K13: =High_Value_Customers!Q12 -> 7
A14: PERFORMANCE KPI | B14: Actual | C14: Target | D14: Variance | E14: Status
A15: Profit Margin | B15: =IF(B9=0,0,B10/B9) -> 0.17748575 | C15: 0.16 | D15: =IFERROR(B15/C15-1,0) -> 0.10928596 | E15: =IF(D15>=0,"On target",IF(D15>=-0.02,"Watch","Below target")) -> On target
A16: Avg Transaction Value | B16: =IF(B11=0,0,B9/B11) -> 29891 | C16: 20000 | D16: =IFERROR(B16/C16-1,0) -> 0.49455 | E16: =IF(D16>=0,"On target",IF(D16>=-0.02,"Watch","Below target")) -> On target
A17: Avg Profit / Transaction | B17: =IF(B11=0,0,B10/B11) -> 5305.2267 | C17: 3000 | D17: =IFERROR(B17/C17-1,0) -> 0.76840889 | E17: =IF(D17>=0,"On target",IF(D17>=-0.02,"Watch","Below target")) -> On target
A18: Avg Units / Transaction | B18: =IF(B11=0,0,B12/B11) -> 3.6666667 | C18: 2 | D18: =IFERROR(B18/C18-1,0) -> 0.83333333 | E18: =IF(D18>=0,"On target",IF(D18>=-0.02,"Watch","Below target")) -> On target

Sheet Report
B1: Customer Transaction Analysis: Final Report
B2: ="Prepared "&TEXT(TODAY(),"dd mmmm yyyy")&" | All figures below are live formulas over the dataset" -> Prepared 30 October 2026 | All figures below are live formulas over the dataset
J3: Insight engine (supporting calculations)
B4: 1. The big picture | J4: Product | K4: Sales | L4: Profit | M4: Margin
B5: ="Between "&TEXT(MIN('Final Project Dataset'!$B$2:$B$251),"d mmm yyyy")&" and "&TEXT(MAX('Final Project Dataset'!$B$2:$B$251),"d mmm yyyy")&", "&COUNT('Final Project Dataset'!$B$2:$B$251)&" transactions from "&COUNTA(High_Value_Customers!$A$8:$A$86)&" customers generated ₹"&TEXT(SUM('Final Project Dataset'!$F$2:$F$251),"#,##0")&" in sales and ₹"&TEXT(SUM('Final Project Dataset'!$H$2:$H$251),"#,##0")&" in profit, a blended margin of "&TEXT(SUM('Final Project Dataset'!$H$2:$H$251)/SUM('Final Project Dataset'!$F$2:$F$251),"0.0%")&". The average basket is ₹"&TEXT(SUM('Final Project Dataset'!$F$2:$F$251)/COUNT('Final Project Dataset'!$B$2:$B$251),"#,##0")&" with "&TEXT(SUM('Final Project Dataset'!$D$2:$D$251)/COUNT('Final Project Dataset'!$B$2:$B$251),"0.0")&" units per order." -> Between 1 Jan 2025 and 30 Dec 2025, 250 transactions from 79 customers generated ₹5,262,053 in sales and ₹800,178 in profit, a blended margin of 15.2%. The average basket is ₹21,048 with 1.9 units per order. | J5: Laptop | K5: =SUMIF('Final Project Dataset'!$C$2:$C$251,J5,'Final Project Dataset'!$F$2:$F$251) -> 1391226 | L5: =SUMIF('Final Project Dataset'!$C$2:$C$251,J5,'Final Project Dataset'!$H$2:$H$251) -> 203150.95 | M5: =L5/K5 -> 0.14602297
J6: Smartphone | K6: =SUMIF('Final Project Dataset'!$C$2:$C$251,J6,'Final Project Dataset'!$F$2:$F$251) -> 969135 | L6: =SUMIF('Final Project Dataset'!$C$2:$C$251,J6,'Final Project Dataset'!$H$2:$H$251) -> 113001.97 | M6: =L6/K6 -> 0.11660086
B7: 2. Products: revenue vs margin | J7: Monitor | K7: =SUMIF('Final Project Dataset'!$C$2:$C$251,J7,'Final Project Dataset'!$F$2:$F$251) -> 839029 | L7: =SUMIF('Final Project Dataset'!$C$2:$C$251,J7,'Final Project Dataset'!$H$2:$H$251) -> 131567.18 | M7: =L7/K7 -> 0.15680886
B8: ="Revenue is concentrated in a few big-ticket items: "&INDEX(J5:J14,MATCH(MAX(K5:K14),K5:K14,0))&" leads with ₹"&TEXT(MAX(K5:K14),"#,##0")&" ("&TEXT(MAX(K5:K14)/SUM(K5:K14),"0.0%")&" of sales), and the top three products together bring in "&TEXT(LARGE(K5:K14,1)/SUM(K5:K14)+LARGE(K5:K14,2)/SUM(K5:K14)+LARGE(K5:K14,3)/SUM(K5:K14),"0.0%")&" of revenue." -> Revenue is concentrated in a few big-ticket items: Laptop leads with ₹1,391,226 (26.4% of sales), and the top three products together bring in 60.8% of revenue. | J8: Tablet | K8: =SUMIF('Final Project Dataset'!$C$2:$C$251,J8,'Final Project Dataset'!$F$2:$F$251) -> 812944 | L8: =SUMIF('Final Project Dataset'!$C$2:$C$251,J8,'Final Project Dataset'!$H$2:$H$251) -> 97842.31 | M8: =L8/K8 -> 0.12035553
B9: ="Margin tells a different story: "&INDEX(J5:J14,MATCH(MAX(M5:M14),M5:M14,0))&" earns the best margin ("&TEXT(MAX(M5:M14),"0.0%")&") while "&INDEX(J5:J14,MATCH(MIN(M5:M14),M5:M14,0))&" earns the lowest ("&TEXT(MIN(M5:M14),"0.0%")&"). "&IF(ISNUMBER(FIND(",",Frequency_Match!B15)),"The most frequently purchased products are "&Frequency_Match!B15&" (tied at "&Frequency_Match!B16&" transactions each)","The most frequently purchased product is "&Frequency_Match!B15&" ("&Frequency_Match!B16&" transactions)")&", so purchase frequency and revenue are driven by different items." -> Margin tells a different story: Mouse earns the best margin (29.5%) while Smartphone earns the lowest (11.7%). The most frequently purchased products are Monitor, Headphones (tied at 30 transactions each), so purchase frequency and revenue are driven by different items. | J9: Smartwatch | K9: =SUMIF('Final Project Dataset'!$C$2:$C$251,J9,'Final Project Dataset'!$F$2:$F$251) -> 451804 | L9: =SUMIF('Final Project Dataset'!$C$2:$C$251,J9,'Final Project Dataset'!$H$2:$H$251) -> 80562.49 | M9: =L9/K9 -> 0.17831292
J10: Printer | K10: =SUMIF('Final Project Dataset'!$C$2:$C$251,J10,'Final Project Dataset'!$F$2:$F$251) -> 323199 | L10: =SUMIF('Final Project Dataset'!$C$2:$C$251,J10,'Final Project Dataset'!$H$2:$H$251) -> 53932.62 | M10: =L10/K10 -> 0.16687125
B11: 3. Regions and timing | J11: Headphones | K11: =SUMIF('Final Project Dataset'!$C$2:$C$251,J11,'Final Project Dataset'!$F$2:$F$251) -> 190247 | L11: =SUMIF('Final Project Dataset'!$C$2:$C$251,J11,'Final Project Dataset'!$H$2:$H$251) -> 49532.28 | M11: =L11/K11 -> 0.26035775
B12: ="By region, "&INDEX(J18:J22,MATCH(MAX(K18:K22),K18:K22,0))&" is the strongest market (₹"&TEXT(MAX(K18:K22),"#,##0")&") and "&INDEX(J18:J22,MATCH(MIN(K18:K22),K18:K22,0))&" the weakest (₹"&TEXT(MIN(K18:K22),"#,##0")&"), a gap of "&TEXT(MAX(K18:K22)/MIN(K18:K22)-1,"0%")&"." -> By region, West is the strongest market (₹1,391,841) and North the weakest (₹852,561), a gap of 63%. | J12: Webcam | K12: =SUMIF('Final Project Dataset'!$C$2:$C$251,J12,'Final Project Dataset'!$F$2:$F$251) -> 155853 | L12: =SUMIF('Final Project Dataset'!$C$2:$C$251,J12,'Final Project Dataset'!$H$2:$H$251) -> 33233.14 | M12: =L12/K12 -> 0.21323388
B13: ="Sales are seasonal: "&TEXT(INDEX(J26:J37,MATCH(MAX(K26:K37),K26:K37,0)),"mmmm")&" is the peak month (₹"&TEXT(MAX(K26:K37),"#,##0")&") and "&TEXT(INDEX(J26:J37,MATCH(MIN(K26:K37),K26:K37,0)),"mmmm")&" the trough (₹"&TEXT(MIN(K26:K37),"#,##0")&"). The most used payment channel by value is "&INDEX(J41:J45,MATCH(MAX(K41:K45),K41:K45,0))&" ("&TEXT(MAX(K41:K45)/SUM(K41:K45),"0%")&" of sales)." -> Sales are seasonal: March is the peak month (₹962,449) and September the trough (₹157,693). The most used payment channel by value is Net Banking (28% of sales). | J13: Keyboard | K13: =SUMIF('Final Project Dataset'!$C$2:$C$251,J13,'Final Project Dataset'!$F$2:$F$251) -> 89109 | L13: =SUMIF('Final Project Dataset'!$C$2:$C$251,J13,'Final Project Dataset'!$H$2:$H$251) -> 25713.01 | M13: =L13/K13 -> 0.28855682
J14: Mouse | K14: =SUMIF('Final Project Dataset'!$C$2:$C$251,J14,'Final Project Dataset'!$F$2:$F$251) -> 39507 | L14: =SUMIF('Final Project Dataset'!$C$2:$C$251,J14,'Final Project Dataset'!$H$2:$H$251) -> 11642.31 | M14: =L14/K14 -> 0.2946898
B15: 4. Customers
B16: ="The top "&TEXT(1-High_Value_Customers!B3,"0%")&" of customers ("&High_Value_Customers!E3&" people with at least ₹"&TEXT(High_Value_Customers!B4,"#,##0")&" in purchases) deliver "&TEXT(High_Value_Customers!E4,"0.0%")&" of all sales, so a small group carries a large part of revenue." -> The top 20% of customers (16 people with at least ₹100,178 in purchases) deliver 46.2% of all sales, so a small group carries a large part of revenue.
B17: ="The biggest customer is "&High_Value_Customers!N8&" with ₹"&TEXT(High_Value_Customers!O8,"#,##0")&" across "&High_Value_Customers!Q8&" purchases. "&Frequency_Match!B19&" customers bought more than once, and "&TEXT(Frequency_Match!B22,"0%")&" of transactions come from repeat names; the most frequent buyer is "&Frequency_Match!B20&" ("&Frequency_Match!B21&" purchases)." -> The biggest customer is Aditya Kapoor with ₹321,673 across 6 purchases. 70 customers bought more than once, and 96% of transactions come from repeat names; the most frequent buyer is Riya Reddy (8 purchases). | J17: Region | K17: Sales | L17: Profit
J18: North | K18: =SUMIF('Final Project Dataset'!$G$2:$G$251,J18,'Final Project Dataset'!$F$2:$F$251) -> 852561 | L18: =SUMIF('Final Project Dataset'!$G$2:$G$251,J18,'Final Project Dataset'!$H$2:$H$251) -> 132198.05
B19: 5. What drives profit (regression) | J19: South | K19: =SUMIF('Final Project Dataset'!$G$2:$G$251,J19,'Final Project Dataset'!$F$2:$F$251) -> 907263 | L19: =SUMIF('Final Project Dataset'!$G$2:$G$251,J19,'Final Project Dataset'!$H$2:$H$251) -> 130463.13
B20: ="Profit rises steadily with sales: each extra ₹1,000 of sales adds about ₹"&TEXT(Regression!B18*1000,"#,##0")&" of profit, and sales alone explain "&TEXT(Regression!B5,"0.0%")&" of profit variation (significance F = "&TEXT(Regression!F12,"0.0E+00")&"). Because the relationship is so strong, growing order value is a reliable profit lever; the gap to a perfect fit comes from product mix, since margins differ by product." -> Profit rises steadily with sales: each extra ₹1,000 of sales adds about ₹137 of profit, and sales alone explain 89.3% of profit variation (significance F = 1.3E-122). Because the relationship is so strong, growing order value is a reliable profit lever; the gap to a perfect fit comes from product mix, since margins differ by product. | J20: East | K20: =SUMIF('Final Project Dataset'!$G$2:$G$251,J20,'Final Project Dataset'!$F$2:$F$251) -> 877262 | L20: =SUMIF('Final Project Dataset'!$G$2:$G$251,J20,'Final Project Dataset'!$H$2:$H$251) -> 117002.59
J21: West | K21: =SUMIF('Final Project Dataset'!$G$2:$G$251,J21,'Final Project Dataset'!$F$2:$F$251) -> 1391841 | L21: =SUMIF('Final Project Dataset'!$G$2:$G$251,J21,'Final Project Dataset'!$H$2:$H$251) -> 224254.78
B22: 6. What-if outlook | J22: Central | K22: =SUMIF('Final Project Dataset'!$G$2:$G$251,J22,'Final Project Dataset'!$F$2:$F$251) -> 1233126 | L22: =SUMIF('Final Project Dataset'!$G$2:$G$251,J22,'Final Project Dataset'!$H$2:$H$251) -> 196259.71
B23: ="Baseline profit is ₹"&TEXT(WhatIf!B5,"#,##0")&". In the optimistic scenario (price "&TEXT(WhatIf!F5,"+0%;-0%")&", volume "&TEXT(WhatIf!F6,"+0%;-0%")&", cost "&TEXT(WhatIf!F7,"+0%;-0%")&") profit would be ₹"&TEXT(WhatIf!F11,"#,##0")&" ("&TEXT(WhatIf!F13,"+0%;-0%")&"); in the pessimistic one it falls to ₹"&TEXT(WhatIf!G11,"#,##0")&" ("&TEXT(WhatIf!G13,"+0%;-0%")&"). To lift profit by "&TEXT(WhatIf!B24,"0%")&" through volume alone, sales volume must grow by "&TEXT(WhatIf!B26,"0.0%")&"." -> Baseline profit is ₹800,178. In the optimistic scenario (price +5%, volume +10%, cost -3%) profit would be ₹1,316,851 (+65%); in the pessimistic one it falls to ₹282,584 (-65%). To lift profit by 20% through volume alone, sales volume must grow by 20.0%.
B25: 7. Recommendations (based on the data as delivered) | J25: Month | K25: Sales
B26: • Protect margin on high-revenue, low-margin lines. Smartphones and Tablets bring in large revenue but earn the thinnest margins (about 12%), so discount discipline there pays off quickly. | J26: =DATE(2025,1,1) -> 45658 | K26: =SUMIFS('Final Project Dataset'!$F$2:$F$251,'Final Project Dataset'!$B$2:$B$251,">="&J26,'Final Project Dataset'!$B$2:$B$251,"<="&EOMONTH(J26,0)) -> 246721
B27: • Bundle high-margin accessories (Keyboards, Mice, Headphones earn 26–29%) with Laptops and Monitors to raise margin per order without needing more customers. | J27: =EDATE(J26,1) -> 45689 | K27: =SUMIFS('Final Project Dataset'!$F$2:$F$251,'Final Project Dataset'!$B$2:$B$251,">="&J27,'Final Project Dataset'!$B$2:$B$251,"<="&EOMONTH(J27,0)) -> 431916
B28: ="• Build a retention programme for the top customers: the top "&TEXT(1-High_Value_Customers!B3,"0%")&" of buyers drive "&TEXT(High_Value_Customers!E4,"0%")&" of sales, and repeat buyers are the cheapest revenue to grow." -> • Build a retention programme for the top customers: the top 20% of buyers drive 46% of sales, and repeat buyers are the cheapest revenue to grow. | J28: =EDATE(J27,1) -> 45717 | K28: =SUMIFS('Final Project Dataset'!$F$2:$F$251,'Final Project Dataset'!$B$2:$B$251,">="&J28,'Final Project Dataset'!$B$2:$B$251,"<="&EOMONTH(J28,0)) -> 962449
B29: • Lift the weakest region with targeted campaigns, and plan stock and promotions around the March peak and the September dip. | J29: =EDATE(J28,1) -> 45748 | K29: =SUMIFS('Final Project Dataset'!$F$2:$F$251,'Final Project Dataset'!$B$2:$B$251,">="&J29,'Final Project Dataset'!$B$2:$B$251,"<="&EOMONTH(J29,0)) -> 180954
J30: =EDATE(J29,1) -> 45778 | K30: =SUMIFS('Final Project Dataset'!$F$2:$F$251,'Final Project Dataset'!$B$2:$B$251,">="&J30,'Final Project Dataset'!$B$2:$B$251,"<="&EOMONTH(J30,0)) -> 418176
B31: 8. Method | J31: =EDATE(J30,1) -> 45809 | K31: =SUMIFS('Final Project Dataset'!$F$2:$F$251,'Final Project Dataset'!$B$2:$B$251,">="&J31,'Final Project Dataset'!$B$2:$B$251,"<="&EOMONTH(J31,0)) -> 331705
B32: Data: 250 transactions (Final Project Dataset sheet). Analysis uses SUMIFS/COUNTIFS pivot-style tables, INDEX/MATCH multi-value filtering, DATEDIF/EOMONTH date logic, and LINEST-equivalent regression formulas. Dashboard filters (drop-downs and date range) work like Slicers and a Timeline; see HowTo for the native Excel versions. | J32: =EDATE(J31,1) -> 45839 | K32: =SUMIFS('Final Project Dataset'!$F$2:$F$251,'Final Project Dataset'!$B$2:$B$251,">="&J32,'Final Project Dataset'!$B$2:$B$251,"<="&EOMONTH(J32,0)) -> 488558
J33: =EDATE(J32,1) -> 45870 | K33: =SUMIFS('Final Project Dataset'!$F$2:$F$251,'Final Project Dataset'!$B$2:$B$251,">="&J33,'Final Project Dataset'!$B$2:$B$251,"<="&EOMONTH(J33,0)) -> 516837
J34: =EDATE(J33,1) -> 45901 | K34: =SUMIFS('Final Project Dataset'!$F$2:$F$251,'Final Project Dataset'!$B$2:$B$251,">="&J34,'Final Project Dataset'!$B$2:$B$251,"<="&EOMONTH(J34,0)) -> 157693
J35: =EDATE(J34,1) -> 45931 | K35: =SUMIFS('Final Project Dataset'!$F$2:$F$251,'Final Project Dataset'!$B$2:$B$251,">="&J35,'Final Project Dataset'!$B$2:$B$251,"<="&EOMONTH(J35,0)) -> 442217
J36: =EDATE(J35,1) -> 45962 | K36: =SUMIFS('Final Project Dataset'!$F$2:$F$251,'Final Project Dataset'!$B$2:$B$251,">="&J36,'Final Project Dataset'!$B$2:$B$251,"<="&EOMONTH(J36,0)) -> 499395
J37: =EDATE(J36,1) -> 45992 | K37: =SUMIFS('Final Project Dataset'!$F$2:$F$251,'Final Project Dataset'!$B$2:$B$251,">="&J37,'Final Project Dataset'!$B$2:$B$251,"<="&EOMONTH(J37,0)) -> 585432
J40: Payment | K40: Sales
J41: Credit Card | K41: =SUMIF('Final Project Dataset'!$J$2:$J$251,J41,'Final Project Dataset'!$F$2:$F$251) -> 1260631
J42: Debit Card | K42: =SUMIF('Final Project Dataset'!$J$2:$J$251,J42,'Final Project Dataset'!$F$2:$F$251) -> 626766
J43: UPI | K43: =SUMIF('Final Project Dataset'!$J$2:$J$251,J43,'Final Project Dataset'!$F$2:$F$251) -> 1053936
...

Sheet Final Project Dataset
A1: transaction_id | B1: date | C1: product | D1: quantity | E1: unit_price | F1: sales | G1: region | H1: profit | I1: customer_id | J1: payment_method | K1: customer_name | L1: Month End (EOMONTH) | M1: Months Ago (DATEDIF) | N1: Days Ago (TODAY) | O1: Profit Margin | P1: Customer Type | Q1: Txn Code | R1: Initials | S1: Filter Flag | T1: Filter Match #
A2: T0001 | B2: 45658 | C2: Headphones | D2: 2 | E2: 3695 | F2: 7390 | G2: Central | H2: 1869.93 | I2: C042 | J2: Cash | K2: Priya Sharma | L2: =EOMONTH(B2,0) -> 45688 | M2: =DATEDIF(B2,TODAY(),"m") -> 21 | N2: =TODAY()-B2 -> 667 | O2: =IF(F2=0,0,H2/F2) -> 0.25303518 | P2: =IF(COUNTIF($K$2:$K$251,K2)>1,"Repeat","One-time") -> Repeat | Q2: =UPPER(LEFT(C2,3))&"-"&TEXT(B2,"MMYY")&"-"&TEXT(F2,"00000") -> HEA-0125-07390 | R2: =LEFT(K2,1)&MID(K2,FIND(" ",K2)+1,1) -> PS | S2: =IF(AND(OR(FILTER_Demo!$B$3="All",G2=FILTER_Demo!$B$3),OR(FILTER_Demo!$B$4="All",C2=FILTER_Demo!$B$4),F2>=FILTER_Demo!$B$5),1,0) -> 0 | T2: =IF(S2=1,SUM($S$2:S2),"")
A3: T0002 | B3: 45661 | C3: Printer | D3: 1 | E3: 9403 | F3: 9403 | G3: South | H3: 1295.91 | I3: C055 | J3: UPI | K3: Pooja Iyer | L3: =EOMONTH(B3,0) -> 45688 | M3: =DATEDIF(B3,TODAY(),"m") -> 21 | N3: =TODAY()-B3 -> 664 | O3: =IF(F3=0,0,H3/F3) -> 0.13781878 | P3: =IF(COUNTIF($K$2:$K$251,K3)>1,"Repeat","One-time") -> Repeat | Q3: =UPPER(LEFT(C3,3))&"-"&TEXT(B3,"MMYY")&"-"&TEXT(F3,"00000") -> PRI-0125-09403 | R3: =LEFT(K3,1)&MID(K3,FIND(" ",K3)+1,1) -> PI | S3: =IF(AND(OR(FILTER_Demo!$B$3="All",G3=FILTER_Demo!$B$3),OR(FILTER_Demo!$B$4="All",C3=FILTER_Demo!$B$4),F3>=FILTER_Demo!$B$5),1,0) -> 0 | T3: =IF(S3=1,SUM($S$2:S3),"")
A4: T0003 | B4: 45661 | C4: Tablet | D4: 2 | E4: 17312 | F4: 34624 | G4: South | H4: 3946.53 | I4: C019 | J4: Net Banking | K4: Aditya Trivedi | L4: =EOMONTH(B4,0) -> 45688 | M4: =DATEDIF(B4,TODAY(),"m") -> 21 | N4: =TODAY()-B4 -> 664 | O4: =IF(F4=0,0,H4/F4) -> 0.1139825 | P4: =IF(COUNTIF($K$2:$K$251,K4)>1,"Repeat","One-time") -> Repeat | Q4: =UPPER(LEFT(C4,3))&"-"&TEXT(B4,"MMYY")&"-"&TEXT(F4,"00000") -> TAB-0125-34624 | R4: =LEFT(K4,1)&MID(K4,FIND(" ",K4)+1,1) -> AT | S4: =IF(AND(OR(FILTER_Demo!$B$3="All",G4=FILTER_Demo!$B$3),OR(FILTER_Demo!$B$4="All",C4=FILTER_Demo!$B$4),F4>=FILTER_Demo!$B$5),1,0) -> 1 | T4: =IF(S4=1,SUM($S$2:S4),"") -> 1
A5: T0004 | B5: 45665 | C5: Webcam | D5: 3 | E5: 2917 | F5: 8751 | G5: Central | H5: 1759.61 | I5: C053 | J5: Credit Card | K5: Manish Nair | L5: =EOMONTH(B5,0) -> 45688 | M5: =DATEDIF(B5,TODAY(),"m") -> 21 | N5: =TODAY()-B5 -> 660 | O5: =IF(F5=0,0,H5/F5) -> 0.20107531 | P5: =IF(COUNTIF($K$2:$K$251,K5)>1,"Repeat","One-time") -> Repeat | Q5: =UPPER(LEFT(C5,3))&"-"&TEXT(B5,"MMYY")&"-"&TEXT(F5,"00000") -> WEB-0125-08751 | R5: =LEFT(K5,1)&MID(K5,FIND(" ",K5)+1,1) -> MN | S5: =IF(AND(OR(FILTER_Demo!$B$3="All",G5=FILTER_Demo!$B$3),OR(FILTER_Demo!$B$4="All",C5=FILTER_Demo!$B$4),F5>=FILTER_Demo!$B$5),1,0) -> 0 | T5: =IF(S5=1,SUM($S$2:S5),"")
A6: T0005 | B6: 45668 | C6: Smartwatch | D6: 5 | E6: 8538 | F6: 42690 | G6: East | H6: 8005.22 | I6: C074 | J6: Credit Card | K6: Anjali Bhatt | L6: =EOMONTH(B6,0) -> 45688 | M6: =DATEDIF(B6,TODAY(),"m") -> 21 | N6: =TODAY()-B6 -> 657 | O6: =IF(F6=0,0,H6/F6) -> 0.18751979 | P6: =IF(COUNTIF($K$2:$K$251,K6)>1,"Repeat","One-time") -> Repeat | Q6: =UPPER(LEFT(C6,3))&"-"&TEXT(B6,"MMYY")&"-"&TEXT(F6,"00000") -> SMA-0125-42690 | R6: =LEFT(K6,1)&MID(K6,FIND(" ",K6)+1,1) -> AB | S6: =IF(AND(OR(FILTER_Demo!$B$3="All",G6=FILTER_Demo!$B$3),OR(FILTER_Demo!$B$4="All",C6=FILTER_Demo!$B$4),F6>=FILTER_Demo!$B$5),1,0) -> 0 | T6: =IF(S6=1,SUM($S$2:S6),"")
A7: T0006 | B7: 45670 | C7: Headphones | D7: 5 | E7: 3718 | F7: 18590 | G7: South | H7: 5356.55 | I7: C043 | J7: Cash | K7: Amit Trivedi | L7: =EOMONTH(B7,0) -> 45688 | M7: =DATEDIF(B7,TODAY(),"m") -> 21 | N7: =TODAY()-B7 -> 655 | O7: =IF(F7=0,0,H7/F7) -> 0.28814147 | P7: =IF(COUNTIF($K$2:$K$251,K7)>1,"Repeat","One-time") -> Repeat | Q7: =UPPER(LEFT(C7,3))&"-"&TEXT(B7,"MMYY")&"-"&TEXT(F7,"00000") -> HEA-0125-18590 | R7: =LEFT(K7,1)&MID(K7,FIND(" ",K7)+1,1) -> AT | S7: =IF(AND(OR(FILTER_Demo!$B$3="All",G7=FILTER_Demo!$B$3),OR(FILTER_Demo!$B$4="All",C7=FILTER_Demo!$B$4),F7>=FILTER_Demo!$B$5),1,0) -> 0 | T7: =IF(S7=1,SUM($S$2:S7),"")
A8: T0007 | B8: 45672 | C8: Keyboard | D8: 1 | E8: 1978 | F8: 1978 | G8: East | H8: 529.1 | I8: C013 | J8: UPI | K8: Vihaan Mehta | L8: =EOMONTH(B8,0) -> 45688 | M8: =DATEDIF(B8,TODAY(),"m") -> 21 | N8: =TODAY()-B8 -> 653 | O8: =IF(F8=0,0,H8/F8) -> 0.26749242 | P8: =IF(COUNTIF($K$2:$K$251,K8)>1,"Repeat","One-time") -> Repeat | Q8: =UPPER(LEFT(C8,3))&"-"&TEXT(B8,"MMYY")&"-"&TEXT(F8,"00000") -> KEY-0125-01978 | R8: =LEFT(K8,1)&MID(K8,FIND(" ",K8)+1,1) -> VM | S8: =IF(AND(OR(FILTER_Demo!$B$3="All",G8=FILTER_Demo!$B$3),OR(FILTER_Demo!$B$4="All",C8=FILTER_Demo!$B$4),F8>=FILTER_Demo!$B$5),1,0) -> 0 | T8: =IF(S8=1,SUM($S$2:S8),"")
A9: T0008 | B9: 45672 | C9: Keyboard | D9: 3 | E9: 1823 | F9: 5469 | G9: North | H9: 1709.19 | I9: C006 | J9: Net Banking | K9: Riya Shah | L9: =EOMONTH(B9,0) -> 45688 | M9: =DATEDIF(B9,TODAY(),"m") -> 21 | N9: =TODAY()-B9 -> 653 | O9: =IF(F9=0,0,H9/F9) -> 0.31252331 | P9: =IF(COUNTIF($K$2:$K$251,K9)>1,"Repeat","One-time") -> Repeat | Q9: =UPPER(LEFT(C9,3))&"-"&TEXT(B9,"MMYY")&"-"&TEXT(F9,"00000") -> KEY-0125-05469 | R9: =LEFT(K9,1)&MID(K9,FIND(" ",K9)+1,1) -> RS | S9: =IF(AND(OR(FILTER_Demo!$B$3="All",G9=FILTER_Demo!$B$3),OR(FILTER_Demo!$B$4="All",C9=FILTER_Demo!$B$4),F9>=FILTER_Demo!$B$5),1,0) -> 0 | T9: =IF(S9=1,SUM($S$2:S9),"")
A10: T0009 | B10: 45674 | C10: Laptop | D10: 1 | E10: 46180 | F10: 46180 | G10: East | H10: 5213.45 | I10: C010 | J10: Net Banking | K10: Vihaan Bhatt | L10: =EOMONTH(B10,0) -> 45688 | M10: =DATEDIF(B10,TODAY(),"m") -> 21 | N10: =TODAY()-B10 -> 651 | O10: =IF(F10=0,0,H10/F10) -> 0.11289411 | P10: =IF(COUNTIF($K$2:$K$251,K10)>1,"Repeat","One-time") -> Repeat | Q10: =UPPER(LEFT(C10,3))&"-"&TEXT(B10,"MMYY")&"-"&TEXT(F10,"00000") -> LAP-0125-46180 | R10: =LEFT(K10,1)&MID(K10,FIND(" ",K10)+1,1) -> VB | S10: =IF(AND(OR(FILTER_Demo!$B$3="All",G10=FILTER_Demo!$B$3),OR(FILTER_Demo!$B$4="All",C10=FILTER_Demo!$B$4),F10>=FILTER_Demo!$B$5),1,0) -> 0 | T10: =IF(S10=1,SUM($S$2:S10),"")
A11: T0010 | B11: 45677 | C11: Smartwatch | D11: 1 | E11: 8460 | F11: 8460 | G11: West | H11: 1191.25 | I11: C029 | J11: Debit Card | K11: Vihaan Iyer | L11: =EOMONTH(B11,0) -> 45688 | M11: =DATEDIF(B11,TODAY(),"m") -> 21 | N11: =TODAY()-B11 -> 648 | O11: =IF(F11=0,0,H11/F11) -> 0.14080969 | P11: =IF(COUNTIF($K$2:$K$251,K11)>1,"Repeat","One-time") -> Repeat | Q11: =UPPER(LEFT(C11,3))&"-"&TEXT(B11,"MMYY")&"-"&TEXT(F11,"00000") -> SMA-0125-08460 | R11: =LEFT(K11,1)&MID(K11,FIND(" ",K11)+1,1) -> VI | S11: =IF(AND(OR(FILTER_Demo!$B$3="All",G11=FILTER_Demo!$B$3),OR(FILTER_Demo!$B$4="All",C11=FILTER_Demo!$B$4),F11>=FILTER_Demo!$B$5),1,0) -> 0 | T11: =IF(S11=1,SUM($S$2:S11),"")
A12: T0011 | B12: 45679 | C12: Webcam | D12: 3 | E12: 2966 | F12: 8898 | G12: East | H12: 2016.23 | I12: C069 | J12: Cash | K12: Aditya Reddy | L12: =EOMONTH(B12,0) -> 45688 | M12: =DATEDIF(B12,TODAY(),"m") -> 21 | N12: =TODAY()-B12 -> 646 | O12: =IF(F12=0,0,H12/F12) -> 0.22659362 | P12: =IF(COUNTIF($K$2:$K$251,K12)>1,"Repeat","One-time") -> Repeat | Q12: =UPPER(LEFT(C12,3))&"-"&TEXT(B12,"MMYY")&"-"&TEXT(F12,"00000") -> WEB-0125-08898 | R12: =LEFT(K12,1)&MID(K12,FIND(" ",K12)+1,1) -> AR | S12: =IF(AND(OR(FILTER_Demo!$B$3="All",G12=FILTER_Demo!$B$3),OR(FILTER_Demo!$B$4="All",C12=FILTER_Demo!$B$4),F12>=FILTER_Demo!$B$5),1,0) -> 0 | T12: =IF(S12=1,SUM($S$2:S12),"")
A13: T0012 | B13: 45679 | C13: Webcam | D13: 2 | E13: 2735 | F13: 5470 | G13: West | H13: 1247.34 | I13: C074 | J13: Debit Card | K13: Anjali Bhatt | L13: =EOMONTH(B13,0) -> 45688 | M13: =DATEDIF(B13,TODAY(),"m") -> 21 | N13: =TODAY()-B13 -> 646 | O13: =IF(F13=0,0,H13/F13) -> 0.22803291 | P13: =IF(COUNTIF($K$2:$K$251,K13)>1,"Repeat","One-time") -> Repeat | Q13: =UPPER(LEFT(C13,3))&"-"&TEXT(B13,"MMYY")&"-"&TEXT(F13,"00000") -> WEB-0125-05470 | R13: =LEFT(K13,1)&MID(K13,FIND(" ",K13)+1,1) -> AB | S13: =IF(AND(OR(FILTER_Demo!$B$3="All",G13=FILTER_Demo!$B$3),OR(FILTER_Demo!$B$4="All",C13=FILTER_Demo!$B$4),F13>=FILTER_Demo!$B$5),1,0) -> 0 | T13: =IF(S13=1,SUM($S$2:S13),"")
... A251: T0250 | B251: 46021 | C251: Printer | D251: 1 | E251: 9120 | F251: 9120 | G251: South | H251: 1146.84 | I251: C047 | J251: Net Banking | K251: Priya Iyer | L251: =EOMONTH(B251,0) -> 46022 | M251: =DATEDIF(B251,TODAY(),"m") -> 10 | N251: =TODAY()-B251 -> 304 | O251: =IF(F251=0,0,H251/F251) -> 0.12575 | P251: =IF(COUNTIF($K$2:$K$251,K251)>1,"Repeat","One-time") -> Repeat | Q251: =UPPER(LEFT(C251,3))&"-"&TEXT(B251,"MMYY")&"-"&TEXT(F251,"00000") -> PRI-1225-09120 | R251: =LEFT(K251,1)&MID(K251,FIND(" ",K251)+1,1) -> PI | S251: =IF(AND(OR(FILTER_Demo!$B$3="All",G251=FILTER_Demo!$B$3),OR(FILTER_Demo!$B$4="All",C251=FILTER_Demo!$B$4),F251>=FILTER_Demo!$B$5),1,0) -> 0 | T251: =IF(S251=1,SUM($S$2:S251),"")

Sheet Pivot_Tables
A1: Pivot-Style Summary Tables (SUMIFS / COUNTIFS) | H1: Filter criteria (from Dashboard)
A2: Responds to the filters on the Dashboard. Source for all dashboard charts. | H2: Region | I2: =IF(Dashboard!$B$3="All","*",Dashboard!$B$3) -> South
A3: By Product | H3: Product | I3: =IF(Dashboard!$B$4="All","*",Dashboard!$B$4) -> Smartwatch
A4: Product | B4: Sales (₹) | C4: Profit (₹) | D4: Transactions | E4: Units | H4: From | I4: =Dashboard!$B$5 -> 45658
A5: Laptop | B5: =SUMIFS('Final Project Dataset'!$F$2:$F$251,'Final Project Dataset'!$C$2:$C$251,$A5,'Final Project Dataset'!$G$2:$G$251,$I$2,'Final Project Dataset'!$C$2:$C$251,$I$3,'Final Project Dataset'!$B$2:$B$251,">="&$I$4,'Final Project Dataset'!$B$2:$B$251,"<="&$I$5) -> 0 | C5: =SUMIFS('Final Project Dataset'!$H$2:$H$251,'Final Project Dataset'!$C$2:$C$251,$A5,'Final Project Dataset'!$G$2:$G$251,$I$2,'Final Project Dataset'!$C$2:$C$251,$I$3,'Final Project Dataset'!$B$2:$B$251,">="&$I$4,'Final Project Dataset'!$B$2:$B$251,"<="&$I$5) -> 0 | D5: =COUNTIFS('Final Project Dataset'!$C$2:$C$251,$A5,'Final Project Dataset'!$G$2:$G$251,$I$2,'Final Project Dataset'!$C$2:$C$251,$I$3,'Final Project Dataset'!$B$2:$B$251,">="&$I$4,'Final Project Dataset'!$B$2:$B$251,"<="&$I$5) -> 0 | E5: =SUMIFS('Final Project Dataset'!$D$2:$D$251,'Final Project Dataset'!$C$2:$C$251,$A5,'Final Project Dataset'!$G$2:$G$251,$I$2,'Final Project Dataset'!$C$2:$C$251,$I$3,'Final Project Dataset'!$B$2:$B$251,">="&$I$4,'Final Project Dataset'!$B$2:$B$251,"<="&$I$5) -> 0 | H5: To | I5: =Dashboard!$B$6 -> 46022
A6: Smartphone | B6: =SUMIFS('Final Project Dataset'!$F$2:$F$251,'Final Project Dataset'!$C$2:$C$251,$A6,'Final Project Dataset'!$G$2:$G$251,$I$2,'Final Project Dataset'!$C$2:$C$251,$I$3,'Final Project Dataset'!$B$2:$B$251,">="&$I$4,'Final Project Dataset'!$B$2:$B$251,"<="&$I$5) -> 0 | C6: =SUMIFS('Final Project Dataset'!$H$2:$H$251,'Final Project Dataset'!$C$2:$C$251,$A6,'Final Project Dataset'!$G$2:$G$251,$I$2,'Final Project Dataset'!$C$2:$C$251,$I$3,'Final Project Dataset'!$B$2:$B$251,">="&$I$4,'Final Project Dataset'!$B$2:$B$251,"<="&$I$5) -> 0 | D6: =COUNTIFS('Final Project Dataset'!$C$2:$C$251,$A6,'Final Project Dataset'!$G$2:$G$251,$I$2,'Final Project Dataset'!$C$2:$C$251,$I$3,'Final Project Dataset'!$B$2:$B$251,">="&$I$4,'Final Project Dataset'!$B$2:$B$251,"<="&$I$5) -> 0 | E6: =SUMIFS('Final Project Dataset'!$D$2:$D$251,'Final Project Dataset'!$C$2:$C$251,$A6,'Final Project Dataset'!$G$2:$G$251,$I$2,'Final Project Dataset'!$C$2:$C$251,$I$3,'Final Project Dataset'!$B$2:$B$251,">="&$I$4,'Final Project Dataset'!$B$2:$B$251,"<="&$I$5) -> 0
A7: Monitor | B7: =SUMIFS('Final Project Dataset'!$F$2:$F$251,'Final Project Dataset'!$C$2:$C$251,$A7,'Final Project Dataset'!$G$2:$G$251,$I$2,'Final Project Dataset'!$C$2:$C$251,$I$3,'Final Project Dataset'!$B$2:$B$251,">="&$I$4,'Final Project Dataset'!$B$2:$B$251,"<="&$I$5) -> 0 | C7: =SUMIFS('Final Project Dataset'!$H$2:$H$251,'Final Project Dataset'!$C$2:$C$251,$A7,'Final Project Dataset'!$G$2:$G$251,$I$2,'Final Project Dataset'!$C$2:$C$251,$I$3,'Final Project Dataset'!$B$2:$B$251,">="&$I$4,'Final Project Dataset'!$B$2:$B$251,"<="&$I$5) -> 0 | D7: =COUNTIFS('Final Project Dataset'!$C$2:$C$251,$A7,'Final Project Dataset'!$G$2:$G$251,$I$2,'Final Project Dataset'!$C$2:$C$251,$I$3,'Final Project Dataset'!$B$2:$B$251,">="&$I$4,'Final Project Dataset'!$B$2:$B$251,"<="&$I$5) -> 0 | E7: =SUMIFS('Final Project Dataset'!$D$2:$D$251,'Final Project Dataset'!$C$2:$C$251,$A7,'Final Project Dataset'!$G$2:$G$251,$I$2,'Final Project Dataset'!$C$2:$C$251,$I$3,'Final Project Dataset'!$B$2:$B$251,">="&$I$4,'Final Project Dataset'!$B$2:$B$251,"<="&$I$5) -> 0
A8: Tablet | B8: =SUMIFS('Final Project Dataset'!$F$2:$F$251,'Final Project Dataset'!$C$2:$C$251,$A8,'Final Project Dataset'!$G$2:$G$251,$I$2,'Final Project Dataset'!$C$2:$C$251,$I$3,'Final Project Dataset'!$B$2:$B$251,">="&$I$4,'Final Project Dataset'!$B$2:$B$251,"<="&$I$5) -> 0 | C8: =SUMIFS('Final Project Dataset'!$H$2:$H$251,'Final Project Dataset'!$C$2:$C$251,$A8,'Final Project Dataset'!$G$2:$G$251,$I$2,'Final Project Dataset'!$C$2:$C$251,$I$3,'Final Project Dataset'!$B$2:$B$251,">="&$I$4,'Final Project Dataset'!$B$2:$B$251,"<="&$I$5) -> 0 | D8: =COUNTIFS('Final Project Dataset'!$C$2:$C$251,$A8,'Final Project Dataset'!$G$2:$G$251,$I$2,'Final Project Dataset'!$C$2:$C$251,$I$3,'Final Project Dataset'!$B$2:$B$251,">="&$I$4,'Final Project Dataset'!$B$2:$B$251,"<="&$I$5) -> 0 | E8: =SUMIFS('Final Project Dataset'!$D$2:$D$251,'Final Project Dataset'!$C$2:$C$251,$A8,'Final Project Dataset'!$G$2:$G$251,$I$2,'Final Project Dataset'!$C$2:$C$251,$I$3,'Final Project Dataset'!$B$2:$B$251,">="&$I$4,'Final Project Dataset'!$B$2:$B$251,"<="&$I$5) -> 0
A9: Smartwatch | B9: =SUMIFS('Final Project Dataset'!$F$2:$F$251,'Final Project Dataset'!$C$2:$C$251,$A9,'Final Project Dataset'!$G$2:$G$251,$I$2,'Final Project Dataset'!$C$2:$C$251,$I$3,'Final Project Dataset'!$B$2:$B$251,">="&$I$4,'Final Project Dataset'!$B$2:$B$251,"<="&$I$5) -> 89673 | C9: =SUMIFS('Final Project Dataset'!$H$2:$H$251,'Final Project Dataset'!$C$2:$C$251,$A9,'Final Project Dataset'!$G$2:$G$251,$I$2,'Final Project Dataset'!$C$2:$C$251,$I$3,'Final Project Dataset'!$B$2:$B$251,">="&$I$4,'Final Project Dataset'!$B$2:$B$251,"<="&$I$5) -> 15915.68 | D9: =COUNTIFS('Final Project Dataset'!$C$2:$C$251,$A9,'Final Project Dataset'!$G$2:$G$251,$I$2,'Final Project Dataset'!$C$2:$C$251,$I$3,'Final Project Dataset'!$B$2:$B$251,">="&$I$4,'Final Project Dataset'!$B$2:$B$251,"<="&$I$5) -> 3 | E9: =SUMIFS('Final Project Dataset'!$D$2:$D$251,'Final Project Dataset'!$C$2:$C$251,$A9,'Final Project Dataset'!$G$2:$G$251,$I$2,'Final Project Dataset'!$C$2:$C$251,$I$3,'Final Project Dataset'!$B$2:$B$251,">="&$I$4,'Final Project Dataset'!$B$2:$B$251,"<="&$I$5) -> 11
A10: Printer | B10: =SUMIFS('Final Project Dataset'!$F$2:$F$251,'Final Project Dataset'!$C$2:$C$251,$A10,'Final Project Dataset'!$G$2:$G$251,$I$2,'Final Project Dataset'!$C$2:$C$251,$I$3,'Final Project Dataset'!$B$2:$B$251,">="&$I$4,'Final Project Dataset'!$B$2:$B$251,"<="&$I$5) -> 0 | C10: =SUMIFS('Final Project Dataset'!$H$2:$H$251,'Final Project Dataset'!$C$2:$C$251,$A10,'Final Project Dataset'!$G$2:$G$251,$I$2,'Final Project Dataset'!$C$2:$C$251,$I$3,'Final Project Dataset'!$B$2:$B$251,">="&$I$4,'Final Project Dataset'!$B$2:$B$251,"<="&$I$5) -> 0 | D10: =COUNTIFS('Final Project Dataset'!$C$2:$C$251,$A10,'Final Project Dataset'!$G$2:$G$251,$I$2,'Final Project Dataset'!$C$2:$C$251,$I$3,'Final Project Dataset'!$B$2:$B$251,">="&$I$4,'Final Project Dataset'!$B$2:$B$251,"<="&$I$5) -> 0 | E10: =SUMIFS('Final Project Dataset'!$D$2:$D$251,'Final Project Dataset'!$C$2:$C$251,$A10,'Final Project Dataset'!$G$2:$G$251,$I$2,'Final Project Dataset'!$C$2:$C$251,$I$3,'Final Project Dataset'!$B$2:$B$251,">="&$I$4,'Final Project Dataset'!$B$2:$B$251,"<="&$I$5) -> 0
A11: Headphones | B11: =SUMIFS('Final Project Dataset'!$F$2:$F$251,'Final Project Dataset'!$C$2:$C$251,$A11,'Final Project Dataset'!$G$2:$G$251,$I$2,'Final Project Dataset'!$C$2:$C$251,$I$3,'Final Project Dataset'!$B$2:$B$251,">="&$I$4,'Final Project Dataset'!$B$2:$B$251,"<="&$I$5) -> 0 | C11: =SUMIFS('Final Project Dataset'!$H$2:$H$251,'Final Project Dataset'!$C$2:$C$251,$A11,'Final Project Dataset'!$G$2:$G$251,$I$2,'Final Project Dataset'!$C$2:$C$251,$I$3,'Final Project Dataset'!$B$2:$B$251,">="&$I$4,'Final Project Dataset'!$B$2:$B$251,"<="&$I$5) -> 0 | D11: =COUNTIFS('Final Project Dataset'!$C$2:$C$251,$A11,'Final Project Dataset'!$G$2:$G$251,$I$2,'Final Project Dataset'!$C$2:$C$251,$I$3,'Final Project Dataset'!$B$2:$B$251,">="&$I$4,'Final Project Dataset'!$B$2:$B$251,"<="&$I$5) -> 0 | E11: =SUMIFS('Final Project Dataset'!$D$2:$D$251,'Final Project Dataset'!$C$2:$C$251,$A11,'Final Project Dataset'!$G$2:$G$251,$I$2,'Final Project Dataset'!$C$2:$C$251,$I$3,'Final Project Dataset'!$B$2:$B$251,">="&$I$4,'Final Project Dataset'!$B$2:$B$251,"<="&$I$5) -> 0
A12: Webcam | B12: =SUMIFS('Final Project Dataset'!$F$2:$F$251,'Final Project Dataset'!$C$2:$C$251,$A12,'Final Project Dataset'!$G$2:$G$251,$I$2,'Final Project Dataset'!$C$2:$C$251,$I$3,'Final Project Dataset'!$B$2:$B$251,">="&$I$4,'Final Project Dataset'!$B$2:$B$251,"<="&$I$5) -> 0 | C12: =SUMIFS('Final Project Dataset'!$H$2:$H$251,'Final Project Dataset'!$C$2:$C$251,$A12,'Final Project Dataset'!$G$2:$G$251,$I$2,'Final Project Dataset'!$C$2:$C$251,$I$3,'Final Project Dataset'!$B$2:$B$251,">="&$I$4,'Final Project Dataset'!$B$2:$B$251,"<="&$I$5) -> 0 | D12: =COUNTIFS('Final Project Dataset'!$C$2:$C$251,$A12,'Final Project Dataset'!$G$2:$G$251,$I$2,'Final Project Dataset'!$C$2:$C$251,$I$3,'Final Project Dataset'!$B$2:$B$251,">="&$I$4,'Final Project Dataset'!$B$2:$B$251,"<="&$I$5) -> 0 | E12: =SUMIFS('Final Project Dataset'!$D$2:$D$251,'Final Project Dataset'!$C$2:$C$251,$A12,'Final Project Dataset'!$G$2:$G$251,$I$2,'Final Project Dataset'!$C$2:$C$251,$I$3,'Final Project Dataset'!$B$2:$B$251,">="&$I$4,'Final Project Dataset'!$B$2:$B$251,"<="&$I$5) -> 0
A13: Keyboard | B13: =SUMIFS('Final Project Dataset'!$F$2:$F$251,'Final Project Dataset'!$C$2:$C$251,$A13,'Final Project Dataset'!$G$2:$G$251,$I$2,'Final Project Dataset'!$C$2:$C$251,$I$3,'Final Project Dataset'!$B$2:$B$251,">="&$I$4,'Final Project Dataset'!$B$2:$B$251,"<="&$I$5) -> 0 | C13: =SUMIFS('Final Project Dataset'!$H$2:$H$251,'Final Project Dataset'!$C$2:$C$251,$A13,'Final Project Dataset'!$G$2:$G$251,$I$2,'Final Project Dataset'!$C$2:$C$251,$I$3,'Final Project Dataset'!$B$2:$B$251,">="&$I$4,'Final Project Dataset'!$B$2:$B$251,"<="&$I$5) -> 0 | D13: =COUNTIFS('Final Project Dataset'!$C$2:$C$251,$A13,'Final Project Dataset'!$G$2:$G$251,$I$2,'Final Project Dataset'!$C$2:$C$251,$I$3,'Final Project Dataset'!$B$2:$B$251,">="&$I$4,'Final Project Dataset'!$B$2:$B$251,"<="&$I$5) -> 0 | E13: =SUMIFS('Final Project Dataset'!$D$2:$D$251,'Final Project Dataset'!$C$2:$C$251,$A13,'Final Project Dataset'!$G$2:$G$251,$I$2,'Final Project Dataset'!$C$2:$C$251,$I$3,'Final Project Dataset'!$B$2:$B$251,">="&$I$4,'Final Project Dataset'!$B$2:$B$251,"<="&$I$5) -> 0
A14: Mouse | B14: =SUMIFS('Final Project Dataset'!$F$2:$F$251,'Final Project Dataset'!$C$2:$C$251,$A14,'Final Project Dataset'!$G$2:$G$251,$I$2,'Final Project Dataset'!$C$2:$C$251,$I$3,'Final Project Dataset'!$B$2:$B$251,">="&$I$4,'Final Project Dataset'!$B$2:$B$251,"<="&$I$5) -> 0 | C14: =SUMIFS('Final Project Dataset'!$H$2:$H$251,'Final Project Dataset'!$C$2:$C$251,$A14,'Final Project Dataset'!$G$2:$G$251,$I$2,'Final Project Dataset'!$C$2:$C$251,$I$3,'Final Project Dataset'!$B$2:$B$251,">="&$I$4,'Final Project Dataset'!$B$2:$B$251,"<="&$I$5) -> 0 | D14: =COUNTIFS('Final Project Dataset'!$C$2:$C$251,$A14,'Final Project Dataset'!$G$2:$G$251,$I$2,'Final Project Dataset'!$C$2:$C$251,$I$3,'Final Project Dataset'!$B$2:$B$251,">="&$I$4,'Final Project Dataset'!$B$2:$B$251,"<="&$I$5) -> 0 | E14: =SUMIFS('Final Project Dataset'!$D$2:$D$251,'Final Project Dataset'!$C$2:$C$251,$A14,'Final Project Dataset'!$G$2:$G$251,$I$2,'Final Project Dataset'!$C$2:$C$251,$I$3,'Final Project Dataset'!$B$2:$B$251,">="&$I$4,'Final Project Dataset'!$B$2:$B$251,"<="&$I$5) -> 0
A15: Grand Total | B15: =SUM(B5:B14) -> 89673 | C15: =SUM(C5:C14) -> 15915.68 | D15: =SUM(D5:D14) -> 3 | E15: =SUM(E5:E14) -> 11
A17: By Region
A18: Region | B18: Sales (₹) | C18: Profit (₹) | D18: Transactions | E18: Units
A19: North | B19: =SUMIFS('Final Project Dataset'!$F$2:$F$251,'Final Project Dataset'!$G$2:$G$251,$A19,'Final Project Dataset'!$G$2:$G$251,$I$2,'Final Project Dataset'!$C$2:$C$251,$I$3,'Final Project Dataset'!$B$2:$B$251,">="&$I$4,'Final Project Dataset'!$B$2:$B$251,"<="&$I$5) -> 0 | C19: =SUMIFS('Final Project Dataset'!$H$2:$H$251,'Final Project Dataset'!$G$2:$G$251,$A19,'Final Project Dataset'!$G$2:$G$251,$I$2,'Final Project Dataset'!$C$2:$C$251,$I$3,'Final Project Dataset'!$B$2:$B$251,">="&$I$4,'Final Project Dataset'!$B$2:$B$251,"<="&$I$5) -> 0 | D19: =COUNTIFS('Final Project Dataset'!$G$2:$G$251,$A19,'Final Project Dataset'!$G$2:$G$251,$I$2,'Final Project Dataset'!$C$2:$C$251,$I$3,'Final Project Dataset'!$B$2:$B$251,">="&$I$4,'Final Project Dataset'!$B$2:$B$251,"<="&$I$5) -> 0 | E19: =SUMIFS('Final Project Dataset'!$D$2:$D$251,'Final Project Dataset'!$G$2:$G$251,$A19,'Final Project Dataset'!$G$2:$G$251,$I$2,'Final Project Dataset'!$C$2:$C$251,$I$3,'Final Project Dataset'!$B$2:$B$251,">="&$I$4,'Final Project Dataset'!$B$2:$B$251,"<="&$I$5) -> 0
A20: South | B20: =SUMIFS('Final Project Dataset'!$F$2:$F$251,'Final Project Dataset'!$G$2:$G$251,$A20,'Final Project Dataset'!$G$2:$G$251,$I$2,'Final Project Dataset'!$C$2:$C$251,$I$3,'Final Project Dataset'!$B$2:$B$251,">="&$I$4,'Final Project Dataset'!$B$2:$B$251,"<="&$I$5) -> 89673 | C20: =SUMIFS('Final Project Dataset'!$H$2:$H$251,'Final Project Dataset'!$G$2:$G$251,$A20,'Final Project Dataset'!$G$2:$G$251,$I$2,'Final Project Dataset'!$C$2:$C$251,$I$3,'Final Project Dataset'!$B$2:$B$251,">="&$I$4,'Final Project Dataset'!$B$2:$B$251,"<="&$I$5) -> 15915.68 | D20: =COUNTIFS('Final Project Dataset'!$G$2:$G$251,$A20,'Final Project Dataset'!$G$2:$G$251,$I$2,'Final Project Dataset'!$C$2:$C$251,$I$3,'Final Project Dataset'!$B$2:$B$251,">="&$I$4,'Final Project Dataset'!$B$2:$B$251,"<="&$I$5) -> 3 | E20: =SUMIFS('Final Project Dataset'!$D$2:$D$251,'Final Project Dataset'!$G$2:$G$251,$A20,'Final Project Dataset'!$G$2:$G$251,$I$2,'Final Project Dataset'!$C$2:$C$251,$I$3,'Final Project Dataset'!$B$2:$B$251,">="&$I$4,'Final Project Dataset'!$B$2:$B$251,"<="&$I$5) -> 11
A21: East | B21: =SUMIFS('Final Project Dataset'!$F$2:$F$251,'Final Project Dataset'!$G$2:$G$251,$A21,'Final Project Dataset'!$G$2:$G$251,$I$2,'Final Project Dataset'!$C$2:$C$251,$I$3,'Final Project Dataset'!$B$2:$B$251,">="&$I$4,'Final Project Dataset'!$B$2:$B$251,"<="&$I$5) -> 0 | C21: =SUMIFS('Final Project Dataset'!$H$2:$H$251,'Final Project Dataset'!$G$2:$G$251,$A21,'Final Project Dataset'!$G$2:$G$251,$I$2,'Final Project Dataset'!$C$2:$C$251,$I$3,'Final Project Dataset'!$B$2:$B$251,">="&$I$4,'Final Project Dataset'!$B$2:$B$251,"<="&$I$5) -> 0 | D21: =COUNTIFS('Final Project Dataset'!$G$2:$G$251,$A21,'Final Project Dataset'!$G$2:$G$251,$I$2,'Final Project Dataset'!$C$2:$C$251,$I$3,'Final Project Dataset'!$B$2:$B$251,">="&$I$4,'Final Project Dataset'!$B$2:$B$251,"<="&$I$5) -> 0 | E21: =SUMIFS('Final Project Dataset'!$D$2:$D$251,'Final Project Dataset'!$G$2:$G$251,$A21,'Final Project Dataset'!$G$2:$G$251,$I$2,'Final Project Dataset'!$C$2:$C$251,$I$3,'Final Project Dataset'!$B$2:$B$251,">="&$I$4,'Final Project Dataset'!$B$2:$B$251,"<="&$I$5) -> 0
A22: West | B22: =SUMIFS('Final Project Dataset'!$F$2:$F$251,'Final Project Dataset'!$G$2:$G$251,$A22,'Final Project Dataset'!$G$2:$G$251,$I$2,'Final Project Dataset'!$C$2:$C$251,$I$3,'Final Project Dataset'!$B$2:$B$251,">="&$I$4,'Final Project Dataset'!$B$2:$B$251,"<="&$I$5) -> 0 | C22: =SUMIFS('Final Project Dataset'!$H$2:$H$251,'Final Project Dataset'!$G$2:$G$251,$A22,'Final Project Dataset'!$G$2:$G$251,$I$2,'Final Project Dataset'!$C$2:$C$251,$I$3,'Final Project Dataset'!$B$2:$B$251,">="&$I$4,'Final Project Dataset'!$B$2:$B$251,"<="&$I$5) -> 0 | D22: =COUNTIFS('Final Project Dataset'!$G$2:$G$251,$A22,'Final Project Dataset'!$G$2:$G$251,$I$2,'Final Project Dataset'!$C$2:$C$251,$I$3,'Final Project Dataset'!$B$2:$B$251,">="&$I$4,'Final Project Dataset'!$B$2:$B$251,"<="&$I$5) -> 0 | E22: =SUMIFS('Final Project Dataset'!$D$2:$D$251,'Final Project Dataset'!$G$2:$G$251,$A22,'Final Project Dataset'!$G$2:$G$251,$I$2,'Final Project Dataset'!$C$2:$C$251,$I$3,'Final Project Dataset'!$B$2:$B$251,">="&$I$4,'Final Project Dataset'!$B$2:$B$251,"<="&$I$5) -> 0
A23: Central | B23: =SUMIFS('Final Project Dataset'!$F$2:$F$251,'Final Project Dataset'!$G$2:$G$251,$A23,'Final Project Dataset'!$G$2:$G$251,$I$2,'Final Project Dataset'!$C$2:$C$251,$I$3,'Final Project Dataset'!$B$2:$B$251,">="&$I$4,'Final Project Dataset'!$B$2:$B$251,"<="&$I$5) -> 0 | C23: =SUMIFS('Final Project Dataset'!$H$2:$H$251,'Final Project Dataset'!$G$2:$G$251,$A23,'Final Project Dataset'!$G$2:$G$251,$I$2,'Final Project Dataset'!$C$2:$C$251,$I$3,'Final Project Dataset'!$B$2:$B$251,">="&$I$4,'Final Project Dataset'!$B$2:$B$251,"<="&$I$5) -> 0 | D23: =COUNTIFS('Final Project Dataset'!$G$2:$G$251,$A23,'Final Project Dataset'!$G$2:$G$251,$I$2,'Final Project Dataset'!$C$2:$C$251,$I$3,'Final Project Dataset'!$B$2:$B$251,">="&$I$4,'Final Project Dataset'!$B$2:$B$251,"<="&$I$5) -> 0 | E23: =SUMIFS('Final Project Dataset'!$D$2:$D$251,'Final Project Dataset'!$G$2:$G$251,$A23,'Final Project Dataset'!$G$2:$G$251,$I$2,'Final Project Dataset'!$C$2:$C$251,$I$3,'Final Project Dataset'!$B$2:$B$251,">="&$I$4,'Final Project Dataset'!$B$2:$B$251,"<="&$I$5) -> 0
A24: Grand Total | B24: =SUM(B19:B23) -> 89673 | C24: =SUM(C19:C23) -> 15915.68 | D24: =SUM(D19:D23) -> 3 | E24: =SUM(E19:E23) -> 11
A26: By Payment Method
A27: Payment Method | B27: Sales (₹) | C27: Profit (₹) | D27: Transactions | E27: Units
A28: Credit Card | B28: =SUMIFS('Final Project Dataset'!$F$2:$F$251,'Final Project Dataset'!$J$2:$J$251,$A28,'Final Project Dataset'!$G$2:$G$251,$I$2,'Final Project Dataset'!$C$2:$C$251,$I$3,'Final Project Dataset'!$B$2:$B$251,">="&$I$4,'Final Project Dataset'!$B$2:$B$251,"<="&$I$5) -> 31036 | C28: =SUMIFS('Final Project Dataset'!$H$2:$H$251,'Final Project Dataset'!$J$2:$J$251,$A28,'Final Project Dataset'!$G$2:$G$251,$I$2,'Final Project Dataset'!$C$2:$C$251,$I$3,'Final Project Dataset'!$B$2:$B$251,">="&$I$4,'Final Project Dataset'!$B$2:$B$251,"<="&$I$5) -> 6292.17 | D28: =COUNTIFS('Final Project Dataset'!$J$2:$J$251,$A28,'Final Project Dataset'!$G$2:$G$251,$I$2,'Final Project Dataset'!$C$2:$C$251,$I$3,'Final Project Dataset'!$B$2:$B$251,">="&$I$4,'Final Project Dataset'!$B$2:$B$251,"<="&$I$5) -> 1 | E28: =SUMIFS('Final Project Dataset'!$D$2:$D$251,'Final Project Dataset'!$J$2:$J$251,$A28,'Final Project Dataset'!$G$2:$G$251,$I$2,'Final Project Dataset'!$C$2:$C$251,$I$3,'Final Project Dataset'!$B$2:$B$251,">="&$I$4,'Final Project Dataset'!$B$2:$B$251,"<="&$I$5) -> 4
A29: Debit Card | B29: =SUMIFS('Final Project Dataset'!$F$2:$F$251,'Final Project Dataset'!$J$2:$J$251,$A29,'Final Project Dataset'!$G$2:$G$251,$I$2,'Final Project Dataset'!$C$2:$C$251,$I$3,'Final Project Dataset'!$B$2:$B$251,">="&$I$4,'Final Project Dataset'!$B$2:$B$251,"<="&$I$5) -> 0 | C29: =SUMIFS('Final Project Dataset'!$H$2:$H$251,'Final Project Dataset'!$J$2:$J$251,$A29,'Final Project Dataset'!$G$2:$G$251,$I$2,'Final Project Dataset'!$C$2:$C$251,$I$3,'Final Project Dataset'!$B$2:$B$251,">="&$I$4,'Final Project Dataset'!$B$2:$B$251,"<="&$I$5) -> 0 | D29: =COUNTIFS('Final Project Dataset'!$J$2:$J$251,$A29,'Final Project Dataset'!$G$2:$G$251,$I$2,'Final Project Dataset'!$C$2:$C$251,$I$3,'Final Project Dataset'!$B$2:$B$251,">="&$I$4,'Final Project Dataset'!$B$2:$B$251,"<="&$I$5) -> 0 | E29: =SUMIFS('Final Project Dataset'!$D$2:$D$251,'Final Project Dataset'!$J$2:$J$251,$A29,'Final Project Dataset'!$G$2:$G$251,$I$2,'Final Project Dataset'!$C$2:$C$251,$I$3,'Final Project Dataset'!$B$2:$B$251,">="&$I$4,'Final Project Dataset'!$B$2:$B$251,"<="&$I$5) -> 0
A30: UPI | B30: =SUMIFS('Final Project Dataset'!$F$2:$F$251,'Final Project Dataset'!$J$2:$J$251,$A30,'Final Project Dataset'!$G$2:$G$251,$I$2,'Final Project Dataset'!$C$2:$C$251,$I$3,'Final Project Dataset'!$B$2:$B$251,">="&$I$4,'Final Project Dataset'!$B$2:$B$251,"<="&$I$5) -> 43305 | C30: =SUMIFS('Final Project Dataset'!$H$2:$H$251,'Final Project Dataset'!$J$2:$J$251,$A30,'Final Project Dataset'!$G$2:$G$251,$I$2,'Final Project Dataset'!$C$2:$C$251,$I$3,'Final Project Dataset'!$B$2:$B$251,">="&$I$4,'Final Project Dataset'!$B$2:$B$251,"<="&$I$5) -> 7627.95 | D30: =COUNTIFS('Final Project Dataset'!$J$2:$J$251,$A30,'Final Project Dataset'!$G$2:$G$251,$I$2,'Final Project Dataset'!$C$2:$C$251,$I$3,'Final Project Dataset'!$B$2:$B$251,">="&$I$4,'Final Project Dataset'!$B$2:$B$251,"<="&$I$5) -> 1 | E30: =SUMIFS('Final Project Dataset'!$D$2:$D$251,'Final Project Dataset'!$J$2:$J$251,$A30,'Final Project Dataset'!$G$2:$G$251,$I$2,'Final Project Dataset'!$C$2:$C$251,$I$3,'Final Project Dataset'!$B$2:$B$251,">="&$I$4,'Final Project Dataset'!$B$2:$B$251,"<="&$I$5) -> 5
A31: Cash | B31: =SUMIFS('Final Project Dataset'!$F$2:$F$251,'Final Project Dataset'!$J$2:$J$251,$A31,'Final Project Dataset'!$G$2:$G$251,$I$2,'Final Project Dataset'!$C$2:$C$251,$I$3,'Final Project Dataset'!$B$2:$B$251,">="&$I$4,'Final Project Dataset'!$B$2:$B$251,"<="&$I$5) -> 15332 | C31: =SUMIFS('Final Project Dataset'!$H$2:$H$251,'Final Project Dataset'!$J$2:$J$251,$A31,'Final Project Dataset'!$G$2:$G$251,$I$2,'Final Project Dataset'!$C$2:$C$251,$I$3,'Final Project Dataset'!$B$2:$B$251,">="&$I$4,'Final Project Dataset'!$B$2:$B$251,"<="&$I$5) -> 1995.56 | D31: =COUNTIFS('Final Project Dataset'!$J$2:$J$251,$A31,'Final Project Dataset'!$G$2:$G$251,$I$2,'Final Project Dataset'!$C$2:$C$251,$I$3,'Final Project Dataset'!$B$2:$B$251,">="&$I$4,'Final Project Dataset'!$B$2:$B$251,"<="&$I$5) -> 1 | E31: =SUMIFS('Final Project Dataset'!$D$2:$D$251,'Final Project Dataset'!$J$2:$J$251,$A31,'Final Project Dataset'!$G$2:$G$251,$I$2,'Final Project Dataset'!$C$2:$C$251,$I$3,'Final Project Dataset'!$B$2:$B$251,">="&$I$4,'Final Project Dataset'!$B$2:$B$251,"<="&$I$5) -> 2
A32: Net Banking | B32: =SUMIFS('Final Project Dataset'!$F$2:$F$251,'Final Project Dataset'!$J$2:$J$251,$A32,'Final Project Dataset'!$G$2:$G$251,$I$2,'Final Project Dataset'!$C$2:$C$251,$I$3,'Final Project Dataset'!$B$2:$B$251,">="&$I$4,'Final Project Dataset'!$B$2:$B$251,"<="&$I$5) -> 0 | C32: =SUMIFS('Final Project Dataset'!$H$2:$H$251,'Final Project Dataset'!$J$2:$J$251,$A32,'Final Project Dataset'!$G$2:$G$251,$I$2,'Final Project Dataset'!$C$2:$C$251,$I$3,'Final Project Dataset'!$B$2:$B$251,">="&$I$4,'Final Project Dataset'!$B$2:$B$251,"<="&$I$5) -> 0 | D32: =COUNTIFS('Final Project Dataset'!$J$2:$J$251,$A32,'Final Project Dataset'!$G$2:$G$251,$I$2,'Final Project Dataset'!$C$2:$C$251,$I$3,'Final Project Dataset'!$B$2:$B$251,">="&$I$4,'Final Project Dataset'!$B$2:$B$251,"<="&$I$5) -> 0 | E32: =SUMIFS('Final Project Dataset'!$D$2:$D$251,'Final Project Dataset'!$J$2:$J$251,$A32,'Final Project Dataset'!$G$2:$G$251,$I$2,'Final Project Dataset'!$C$2:$C$251,$I$3,'Final Project Dataset'!$B$2:$B$251,">="&$I$4,'Final Project Dataset'!$B$2:$B$251,"<="&$I$5) -> 0
A33: Grand Total | B33: =SUM(B28:B32) -> 89673 | C33: =SUM(C28:C32) -> 15915.68 | D33: =SUM(D28:D32) -> 3 | E33: =SUM(E28:E32) -> 11
A35: By Month (timeline)
A36: Month | B36: Sales (₹) | C36: Profit (₹) | D36: Transactions | E36: Units | F36: Label
A37: =DATE(2025,1,1) -> 45658 | B37: =SUMIFS('Final Project Dataset'!$F$2:$F$251,'Final Project Dataset'!$G$2:$G$251,$I$2,'Final Project Dataset'!$C$2:$C$251,$I$3,'Final Project Dataset'!$B$2:$B$251,">="&MAX($A37,$I$4),'Final Project Dataset'!$B$2:$B$251,"<="&MIN(EOMONTH($A37,0),$I$5)) -> 0 | C37: =SUMIFS('Final Project Dataset'!$H$2:$H$251,'Final Project Dataset'!$G$2:$G$251,$I$2,'Final Project Dataset'!$C$2:$C$251,$I$3,'Final Project Dataset'!$B$2:$B$251,">="&MAX($A37,$I$4),'Final Project Dataset'!$B$2:$B$251,"<="&MIN(EOMONTH($A37,0),$I$5)) -> 0 | D37: =COUNTIFS('Final Project Dataset'!$G$2:$G$251,$I$2,'Final Project Dataset'!$C$2:$C$251,$I$3,'Final Project Dataset'!$B$2:$B$251,">="&MAX($A37,$I$4),'Final Project Dataset'!$B$2:$B$251,"<="&MIN(EOMONTH($A37,0),$I$5)) -> 0 | E37: =SUMIFS('Final Project Dataset'!$D$2:$D$251,'Final Project Dataset'!$G$2:$G$251,$I$2,'Final Project Dataset'!$C$2:$C$251,$I$3,'Final Project Dataset'!$B$2:$B$251,">="&MAX($A37,$I$4),'Final Project Dataset'!$B$2:$B$251,"<="&MIN(EOMONTH($A37,0),$I$5)) -> 0 | F37: =TEXT(A37,"mmm yy") -> Jan 25
A38: =EDATE(A37,1) -> 45689 | B38: =SUMIFS('Final Project Dataset'!$F$2:$F$251,'Final Project Dataset'!$G$2:$G$251,$I$2,'Final Project Dataset'!$C$2:$C$251,$I$3,'Final Project Dataset'!$B$2:$B$251,">="&MAX($A38,$I$4),'Final Project Dataset'!$B$2:$B$251,"<="&MIN(EOMONTH($A38,0),$I$5)) -> 0 | C38: =SUMIFS('Final Project Dataset'!$H$2:$H$251,'Final Project Dataset'!$G$2:$G$251,$I$2,'Final Project Dataset'!$C$2:$C$251,$I$3,'Final Project Dataset'!$B$2:$B$251,">="&MAX($A38,$I$4),'Final Project Dataset'!$B$2:$B$251,"<="&MIN(EOMONTH($A38,0),$I$5)) -> 0 | D38: =COUNTIFS('Final Project Dataset'!$G$2:$G$251,$I$2,'Final Project Dataset'!$C$2:$C$251,$I$3,'Final Project Dataset'!$B$2:$B$251,">="&MAX($A38,$I$4),'Final Project Dataset'!$B$2:$B$251,"<="&MIN(EOMONTH($A38,0),$I$5)) -> 0 | E38: =SUMIFS('Final Project Dataset'!$D$2:$D$251,'Final Project Dataset'!$G$2:$G$251,$I$2,'Final Project Dataset'!$C$2:$C$251,$I$3,'Final Project Dataset'!$B$2:$B$251,">="&MAX($A38,$I$4),'Final Project Dataset'!$B$2:$B$251,"<="&MIN(EOMONTH($A38,0),$I$5)) -> 0 | F38: =TEXT(A38,"mmm yy") -> Feb 25
A39: =EDATE(A38,1) -> 45717 | B39: =SUMIFS('Final Project Dataset'!$F$2:$F$251,'Final Project Dataset'!$G$2:$G$251,$I$2,'Final Project Dataset'!$C$2:$C$251,$I$3,'Final Project Dataset'!$B$2:$B$251,">="&MAX($A39,$I$4),'Final Project Dataset'!$B$2:$B$251,"<="&MIN(EOMONTH($A39,0),$I$5)) -> 43305 | C39: =SUMIFS('Final Project Dataset'!$H$2:$H$251,'Final Project Dataset'!$G$2:$G$251,$I$2,'Final Project Dataset'!$C$2:$C$251,$I$3,'Final Project Dataset'!$B$2:$B$251,">="&MAX($A39,$I$4),'Final Project Dataset'!$B$2:$B$251,"<="&MIN(EOMONTH($A39,0),$I$5)) -> 7627.95 | D39: =COUNTIFS('Final Project Dataset'!$G$2:$G$251,$I$2,'Final Project Dataset'!$C$2:$C$251,$I$3,'Final Project Dataset'!$B$2:$B$251,">="&MAX($A39,$I$4),'Final Project Dataset'!$B$2:$B$251,"<="&MIN(EOMONTH($A39,0),$I$5)) -> 1 | E39: =SUMIFS('Final Project Dataset'!$D$2:$D$251,'Final Project Dataset'!$G$2:$G$251,$I$2,'Final Project Dataset'!$C$2:$C$251,$I$3,'Final Project Dataset'!$B$2:$B$251,">="&MAX($A39,$I$4),'Final Project Dataset'!$B$2:$B$251,"<="&MIN(EOMONTH($A39,0),$I$5)) -> 5 | F39: =TEXT(A39,"mmm yy") -> Mar 25
A40: =EDATE(A39,1) -> 45748 | B40: =SUMIFS('Final Project Dataset'!$F$2:$F$251,'Final Project Dataset'!$G$2:$G$251,$I$2,'Final Project Dataset'!$C$2:$C$251,$I$3,'Final Project Dataset'!$B$2:$B$251,">="&MAX($A40,$I$4),'Final Project Dataset'!$B$2:$B$251,"<="&MIN(EOMONTH($A40,0),$I$5)) -> 0 | C40: =SUMIFS('Final Project Dataset'!$H$2:$H$251,'Final Project Dataset'!$G$2:$G$251,$I$2,'Final Project Dataset'!$C$2:$C$251,$I$3,'Final Project Dataset'!$B$2:$B$251,">="&MAX($A40,$I$4),'Final Project Dataset'!$B$2:$B$251,"<="&MIN(EOMONTH($A40,0),$I$5)) -> 0 | D40: =COUNTIFS('Final Project Dataset'!$G$2:$G$251,$I$2,'Final Project Dataset'!$C$2:$C$251,$I$3,'Final Project Dataset'!$B$2:$B$251,">="&MAX($A40,$I$4),'Final Project Dataset'!$B$2:$B$251,"<="&MIN(EOMONTH($A40,0),$I$5)) -> 0 | E40: =SUMIFS('Final Project Dataset'!$D$2:$D$251,'Final Project Dataset'!$G$2:$G$251,$I$2,'Final Project Dataset'!$C$2:$C$251,$I$3,'Final Project Dataset'!$B$2:$B$251,">="&MAX($A40,$I$4),'Final Project Dataset'!$B$2:$B$251,"<="&MIN(EOMONTH($A40,0),$I$5)) -> 0 | F40: =TEXT(A40,"mmm yy") -> Apr 25
A41: =EDATE(A40,1) -> 45778 | B41: =SUMIFS('Final Project Dataset'!$F$2:$F$251,'Final Project Dataset'!$G$2:$G$251,$I$2,'Final Project Dataset'!$C$2:$C$251,$I$3,'Final Project Dataset'!$B$2:$B$251,">="&MAX($A41,$I$4),'Final Project Dataset'!$B$2:$B$251,"<="&MIN(EOMONTH($A41,0),$I$5)) -> 0 | C41: =SUMIFS('Final Project Dataset'!$H$2:$H$251,'Final Project Dataset'!$G$2:$G$251,$I$2,'Final Project Dataset'!$C$2:$C$251,$I$3,'Final Project Dataset'!$B$2:$B$251,">="&MAX($A41,$I$4),'Final Project Dataset'!$B$2:$B$251,"<="&MIN(EOMONTH($A41,0),$I$5)) -> 0 | D41: =COUNTIFS('Final Project Dataset'!$G$2:$G$251,$I$2,'Final Project Dataset'!$C$2:$C$251,$I$3,'Final Project Dataset'!$B$2:$B$251,">="&MAX($A41,$I$4),'Final Project Dataset'!$B$2:$B$251,"<="&MIN(EOMONTH($A41,0),$I$5)) -> 0 | E41: =SUMIFS('Final Project Dataset'!$D$2:$D$251,'Final Project Dataset'!$G$2:$G$251,$I$2,'Final Project Dataset'!$C$2:$C$251,$I$3,'Final Project Dataset'!$B$2:$B$251,">="&MAX($A41,$I$4),'Final Project Dataset'!$B$2:$B$251,"<="&MIN(EOMONTH($A41,0),$I$5)) -> 0 | F41: =TEXT(A41,"mmm yy") -> May 25
A42: =EDATE(A41,1) -> 45809 | B42: =SUMIFS('Final Project Dataset'!$F$2:$F$251,'Final Project Dataset'!$G$2:$G$251,$I$2,'Final Project Dataset'!$C$2:$C$251,$I$3,'Final Project Dataset'!$B$2:$B$251,">="&MAX($A42,$I$4),'Final Project Dataset'!$B$2:$B$251,"<="&MIN(EOMONTH($A42,0),$I$5)) -> 15332 | C42: =SUMIFS('Final Project Dataset'!$H$2:$H$251,'Final Project Dataset'!$G$2:$G$251,$I$2,'Final Project Dataset'!$C$2:$C$251,$I$3,'Final Project Dataset'!$B$2:$B$251,">="&MAX($A42,$I$4),'Final Project Dataset'!$B$2:$B$251,"<="&MIN(EOMONTH($A42,0),$I$5)) -> 1995.56 | D42: =COUNTIFS('Final Project Dataset'!$G$2:$G$251,$I$2,'Final Project Dataset'!$C$2:$C$251,$I$3,'Final Project Dataset'!$B$2:$B$251,">="&MAX($A42,$I$4),'Final Project Dataset'!$B$2:$B$251,"<="&MIN(EOMONTH($A42,0),$I$5)) -> 1 | E42: =SUMIFS('Final Project Dataset'!$D$2:$D$251,'Final Project Dataset'!$G$2:$G$251,$I$2,'Final Project Dataset'!$C$2:$C$251,$I$3,'Final Project Dataset'!$B$2:$B$251,">="&MAX($A42,$I$4),'Final Project Dataset'!$B$2:$B$251,"<="&MIN(EOMONTH($A42,0),$I$5)) -> 2 | F42: =TEXT(A42,"mmm yy") -> Jun 25
A43: =EDATE(A42,1) -> 45839 | B43: =SUMIFS('Final Project Dataset'!$F$2:$F$251,'Final Project Dataset'!$G$2:$G$251,$I$2,'Final Project Dataset'!$C$2:$C$251,$I$3,'Final Project Dataset'!$B$2:$B$251,">="&MAX($A43,$I$4),'Final Project Dataset'!$B$2:$B$251,"<="&MIN(EOMONTH($A43,0),$I$5)) -> 0 | C43: =SUMIFS('Final Project Dataset'!$H$2:$H$251,'Final Project Dataset'!$G$2:$G$251,$I$2,'Final Project Dataset'!$C$2:$C$251,$I$3,'Final Project Dataset'!$B$2:$B$251,">="&MAX($A43,$I$4),'Final Project Dataset'!$B$2:$B$251,"<="&MIN(EOMONTH($A43,0),$I$5)) -> 0 | D43: =COUNTIFS('Final Project Dataset'!$G$2:$G$251,$I$2,'Final Project Dataset'!$C$2:$C$251,$I$3,'Final Project Dataset'!$B$2:$B$251,">="&MAX($A43,$I$4),'Final Project Dataset'!$B$2:$B$251,"<="&MIN(EOMONTH($A43,0),$I$5)) -> 0 | E43: =SUMIFS('Final Project Dataset'!$D$2:$D$251,'Final Project Dataset'!$G$2:$G$251,$I$2,'Final Project Dataset'!$C$2:$C$251,$I$3,'Final Project Dataset'!$B$2:$B$251,">="&MAX($A43,$I$4),'Final Project Dataset'!$B$2:$B$251,"<="&MIN(EOMONTH($A43,0),$I$5)) -> 0 | F43: =TEXT(A43,"mmm yy") -> Jul 25
...

Sheet FILTER_Demo
A1: Multi-Value Return (FILTER-style)
A2: Pick criteria; matching rows are returned below. Built with helper columns + INDEX/MATCH so it works in every Excel version.
A3: Region | B3: All | D3: Excel 365 equivalent (one formula, spills automatically):
A4: Product | B4: Tablet | D4: FILTER(Data[A2:K251], (Data[Region]=B3)*(Data[Product]=B4)*(Data[Sales]>=B5), "No match")
A5: Min sales (₹) | B5: 0 | D5: Showing the first 25 matches below.
A7: Matching rows | B7: =SUM('Final Project Dataset'!$S$2:$S$251) -> 22
A9: # | B9: Txn ID | C9: Date | D9: Product | E9: Qty | F9: Sales (₹) | G9: Region | H9: Profit (₹) | I9: Customer
A10: 1 | B10: =IFERROR(INDEX('Final Project Dataset'!$A$2:$A$251,MATCH($A10,'Final Project Dataset'!$T$2:$T$251,0)),"") -> T0003 | C10: =IFERROR(INDEX('Final Project Dataset'!$B$2:$B$251,MATCH($A10,'Final Project Dataset'!$T$2:$T$251,0)),"") -> 45661 | D10: =IFERROR(INDEX('Final Project Dataset'!$C$2:$C$251,MATCH($A10,'Final Project Dataset'!$T$2:$T$251,0)),"") -> Tablet | E10: =IFERROR(INDEX('Final Project Dataset'!$D$2:$D$251,MATCH($A10,'Final Project Dataset'!$T$2:$T$251,0)),"") -> 2 | F10: =IFERROR(INDEX('Final Project Dataset'!$F$2:$F$251,MATCH($A10,'Final Project Dataset'!$T$2:$T$251,0)),"") -> 34624 | G10: =IFERROR(INDEX('Final Project Dataset'!$G$2:$G$251,MATCH($A10,'Final Project Dataset'!$T$2:$T$251,0)),"") -> South | H10: =IFERROR(INDEX('Final Project Dataset'!$H$2:$H$251,MATCH($A10,'Final Project Dataset'!$T$2:$T$251,0)),"") -> 3946.53 | I10: =IFERROR(INDEX('Final Project Dataset'!$K$2:$K$251,MATCH($A10,'Final Project Dataset'!$T$2:$T$251,0)),"") -> Aditya Trivedi
A11: 2 | B11: =IFERROR(INDEX('Final Project Dataset'!$A$2:$A$251,MATCH($A11,'Final Project Dataset'!$T$2:$T$251,0)),"") -> T0020 | C11: =IFERROR(INDEX('Final Project Dataset'!$B$2:$B$251,MATCH($A11,'Final Project Dataset'!$T$2:$T$251,0)),"") -> 45689 | D11: =IFERROR(INDEX('Final Project Dataset'!$C$2:$C$251,MATCH($A11,'Final Project Dataset'!$T$2:$T$251,0)),"") -> Tablet | E11: =IFERROR(INDEX('Final Project Dataset'!$D$2:$D$251,MATCH($A11,'Final Project Dataset'!$T$2:$T$251,0)),"") -> 1 | F11: =IFERROR(INDEX('Final Project Dataset'!$F$2:$F$251,MATCH($A11,'Final Project Dataset'!$T$2:$T$251,0)),"") -> 16411 | G11: =IFERROR(INDEX('Final Project Dataset'!$G$2:$G$251,MATCH($A11,'Final Project Dataset'!$T$2:$T$251,0)),"") -> East | H11: =IFERROR(INDEX('Final Project Dataset'!$H$2:$H$251,MATCH($A11,'Final Project Dataset'!$T$2:$T$251,0)),"") -> 2520.3 | I11: =IFERROR(INDEX('Final Project Dataset'!$K$2:$K$251,MATCH($A11,'Final Project Dataset'!$T$2:$T$251,0)),"") -> Amit Singh
A12: 3 | B12: =IFERROR(INDEX('Final Project Dataset'!$A$2:$A$251,MATCH($A12,'Final Project Dataset'!$T$2:$T$251,0)),"") -> T0030 | C12: =IFERROR(INDEX('Final Project Dataset'!$B$2:$B$251,MATCH($A12,'Final Project Dataset'!$T$2:$T$251,0)),"") -> 45705 | D12: =IFERROR(INDEX('Final Project Dataset'!$C$2:$C$251,MATCH($A12,'Final Project Dataset'!$T$2:$T$251,0)),"") -> Tablet | E12: =IFERROR(INDEX('Final Project Dataset'!$D$2:$D$251,MATCH($A12,'Final Project Dataset'!$T$2:$T$251,0)),"") -> 1 | F12: =IFERROR(INDEX('Final Project Dataset'!$F$2:$F$251,MATCH($A12,'Final Project Dataset'!$T$2:$T$251,0)),"") -> 19646 | G12: =IFERROR(INDEX('Final Project Dataset'!$G$2:$G$251,MATCH($A12,'Final Project Dataset'!$T$2:$T$251,0)),"") -> West | H12: =IFERROR(INDEX('Final Project Dataset'!$H$2:$H$251,MATCH($A12,'Final Project Dataset'!$T$2:$T$251,0)),"") -> 2232.95 | I12: =IFERROR(INDEX('Final Project Dataset'!$K$2:$K$251,MATCH($A12,'Final Project Dataset'!$T$2:$T$251,0)),"") -> Vihaan Mehta
